File: Notebooks/Exercise data/Oxidised MWCNTs_3.txt
#Acq. time (s)=	3
#Accumulations=	10
#Range (cm-¹)=	100...3500
#Windows=	6
#Autofocus=	Off
#AutoExposure=	Off
#Spike filter=	Multiple accum.
#Delay time (s)=	0
#Binning=	1
#Readout mode=	Signal
#DeNoise=	Off
#ICS correction=	Off
#Dark correction=	Off
#Inst. Process=	Off
#Instrument=	ARAMIS
#Detector=	Andor CCD
#Objective=	x50 SLWD
#Grating=	1800
#Filter=	100%
#Laser (nm)=	532
#Slit=	150
#Hole=	400
#Location=	Micro
#Range=	VIS
#StageXY=	Marzhauser
#StageZ=	Marzhauser
#X (µm)=	-5189.6
#Y (µm)=	-12843.1
#Z (µm)=	498.45
#Project=
#Sample=
#Site=
#Title=	Oxidised MWCNTs 30_3
#Remark=
#Date=	06.03.2020 12:34
#Acquired=	06.03.2020 12:34:50
100.291	259.444
103.86	276.438
107.427	273.987
110.993	293.425
114.556	304.974
118.119	259.412
121.679	247.183
125.235	236.954
128.793	243.281
132.346	259.497
135.899	206.49
139.45	198.928
142.997	194.255
146.543	194.359
150.088	186.353
153.632	191.124
157.172	179.006
160.71	188.555
164.247	179.549
167.783	181.431
171.316	175.091
174.847	181.973
178.377	168.633
181.903	182.071
185.428	175.176
188.952	174.28
192.474	174.941
195.993	169.601
199.511	178.039
203.027	173.254
206.542	175.025
210.054	175.908
213.564	170.679
217.073	173.672
220.58	176.666
224.084	175.548
227.587	175.764
231.086	182.313
234.586	182.862
238.083	180.744
241.579	173.293
245.071	177.064
248.563	180.836
252.053	171.273
255.541	180.822
259.025	185.483
262.509	177.92
265.991	176.581
269.471	176.352
272.949	179.345
276.427	179.561
279.899	173.11
283.373	172.103
286.843	172.986
290.311	172.201
293.779	164.417
297.243	164.41
300.707	162.515
304.169	161.397
307.627	161.168
311.086	154.051
314.541	154.6
317.993	150.482
321.446	154.364
324.896	149.469
328.344	150.462
331.791	145.456
335.234	139.227
338.676	139.887
342.117	143.77
345.557	139.763
348.993	142.09
352.428	136.528
355.862	133.854
359.293	139.626
362.722	141.397
366.15	135.279
369.576	129.939
373	131.044
376.422	130.259
379.842	136.697
383.26	130.024
386.676	131.129
390.091	132.011
393.504	131.338
396.914	131.553
400.323	133.214
403.731	135.207
407.135	134.089
410.538	138.194
413.94	130.187
417.341	136.625
420.738	135.73
424.134	136.723
427.529	136.828
430.92	135.821
434.311	132.592
437.7	133.586
441.087	131.801
444.472	127.462
447.855	133.122
451.237	128.226
454.615	131.664
457.993	135.991
461.369	132.984
464.744	129.311
468.115	130.749
471.486	126.076
474.855	123.625
478.221	125.84
481.585	126.945
484.948	121.272
488.309	122.71
491.669	121.814
495.027	121.919
498.381	124.468
501.736	118.906
505.088	117.455
508.437	120.004
511.786	122.219
515.133	115.324
518.477	116.317
521.819	114.533
525.161	110.082
528.501	111.853
531.837	115.513
535.173	114.84
538.507	115.833
541.839	110.827
545.168	115.931
548.496	112.703
551.823	115.696
555.148	111.467
558.47	113.572
561.791	118.788
565.111	112.003
568.428	116.552
571.743	115.657
575.057	116.984
578.37	113.421
581.68	113.748
584.988	113.075
588.293	117.513
591.599	115.84
594.902	110.833
598.202	114.826
601.502	117.153
604.799	115.924
608.096	118.14
611.388	114.467
614.68	113.905
617.97	115.454
621.26	113.114
624.546	114.33
627.831	114.101
631.114	116.761
634.395	114.865
637.674	121.081
640.952	119.741
644.229	115.735
647.503	119.284
650.775	112.499
654.045	116.159
657.313	123.486
660.58	118.591
663.846	122.917
667.108	116.689
670.37	119.015
673.63	113.676
676.887	117.558
680.145	118.996
683.398	117.989
686.651	114.538
689.902	115.643
693.151	118.97
696.399	117.741
699.644	114.512
702.888	114.728
706.129	118.832
709.37	114.048
712.608	116.708
715.843	113.924
719.079	118.362
722.312	110.244
725.544	113.46
728.772	113.342
732	109.669
735.226	113.551
738.451	117.989
741.673	111.093
744.894	110.753
748.111	114.525
751.33	116.074
754.545	109.289
757.757	112.616
760.97	107.165
764.18	107.603
767.387	111.596
770.595	119.479
773.799	112.806
777.003	113.91
780.203	112.792
783.402	112.008
786.6	111.779
789.797	108.995
792.991	114.544
796.183	109.649
799.373	105.864
802.563	109.413
805.75	115.851
808.934	112.733
812.117	109.727
815.299	114.72
818.48	117.269
821.658	113.485
824.834	109.478
828.01	110.805
831.184	111.132
834.355	113.57
837.523	111.119
840.692	111.557
843.858	114.772
847.023	110.988
850.184	112.093
853.345	114.197
856.504	117.413
859.663	114.406
862.818	109.4
865.972	111.282
869.123	110.335
872.273	106.43
875.422	108.072
878.57	110.207
881.715	106.58
884.858	108.965
888.001	108.408
891.14	111.855
894.278	111.11
897.416	109.551
900.55	110.279
903.683	113.095
906.815	113.536
909.944	114.432
913.072	114.855
916.198	116.851
919.322	117.223
922.445	119.616
925.566	118.449
928.685	122.501
931.802	119.612
934.918	123.338
938.032	123.543
941.144	124.267
944.255	126.999
947.365	127.018
950.025	127.572
953.207	129.431
956.383	133.513
959.561	130.261
962.736	126.898
965.909	135.091
969.081	131.617
972.251	135.921
975.419	133.225
978.586	133.084
981.752	137.499
984.914	147.803
988.076	140.773
991.237	146.521
994.394	142.381
997.553	143.573
1000.71	146.988
1003.86	144.292
1007.01	147.485
1010.16	145.122
1013.31	149.314
1016.46	152.618
1019.6	151.255
1022.75	154.448
1025.89	158.974
1029.03	158.944
1032.17	163.248
1035.3	157.774
1038.44	170.411
1041.57	169.048
1044.7	166.241
1047.83	169.1
1050.96	171.404
1054.09	181.486
1057.21	183.012
1060.34	190.316
1063.46	191.175
1066.58	190.479
1069.7	198.894
1072.81	197.42
1075.93	205.279
1079.04	210.583
1082.15	208.998
1085.26	212.524
1088.37	211.494
1091.48	219.131
1094.59	214.324
1097.69	218.405
1100.79	217.154
1103.89	214.569
1106.99	220.317
1110.09	220.065
1113.18	212.48
1116.28	214.45
1119.37	217.088
1122.46	210.502
1125.55	212.251
1128.64	216.777
1131.72	217.858
1134.81	212.718
1137.89	214.799
1140.97	211.77
1144.05	214.073
1147.13	215.933
1150.2	204.903
1153.28	210.874
1156.35	209.177
1159.42	214.814
1162.49	216.896
1165.56	211.089
1168.62	210.393
1171.69	219.252
1174.75	214.445
1177.81	216.304
1180.87	218.497
1183.93	222.245
1186.99	223.993
1190.04	223.852
1193.09	222.045
1196.14	225.904
1199.19	226.208
1202.24	227.179
1205.29	226.149
1208.33	227.786
1211.38	231.979
1214.42	238.616
1217.46	242.698
1220.5	242.668
1223.53	247.305
1226.57	244.387
1229.6	252.024
1232.63	251.328
1235.67	251.298
1238.69	263.268
1241.72	260.128
1244.75	270.765
1247.77	268.958
1250.79	274.15
1253.81	281.232
1256.83	282.424
1259.85	293.617
1262.87	308.699
1265.88	302.447
1268.89	312.529
1271.9	324.166
1274.91	333.358
1277.92	341.329
1280.93	353.41
1283.93	367.27
1286.93	389.462
1289.94	403.322
1292.94	413.292
1295.93	446.263
1298.93	480.566
1301.93	509.759
1304.92	549.063
1307.91	602.478
1310.9	664.67
1313.89	727.863
1316.88	799.722
1319.86	914.026
1322.85	1014.77
1325.83	1132.52
1328.81	1229.16
1331.79	1365.69
1334.76	1468.66
1337.74	1503.18
1340.71	1507.82
1343.69	1428.79
1346.66	1339.65
1349.63	1235.62
1352.6	1101.92
1355.56	989.227
1358.53	895.753
1361.49	795.057
1364.45	724.138
1367.41	658.109
1370.37	610.079
1373.33	542.605
1376.28	513.576
1379.23	482.88
1382.19	443.628
1385.14	434.154
1388.09	406.235
1391.03	402.873
1393.98	380.287
1396.92	369.702
1399.87	362.451
1402.81	353.31
1405.75	350.392
1408.68	333.806
1411.62	338.666
1414.55	333.858
1417.49	328.051
1420.42	328.577
1423.35	319.214
1426.28	322.074
1429.2	318.377
1432.13	321.903
1435.05	322.318
1437.97	323.289
1440.89	329.926
1443.81	327.563
1446.73	325.311
1449.65	322.948
1452.56	330.03
1455.47	324.889
1458.38	329.971
1461.29	322.608
1464.2	327.912
1467.11	323.882
1470.01	331.408
1472.92	334.379
1475.82	328.571
1478.72	341.208
1481.62	341.401
1484.51	345.371
1487.41	341.12
1490.3	358.312
1493.19	355.616
1496.08	366.364
1498.97	355.668
1501.86	371.194
1504.75	377.054
1507.63	395.135
1510.52	404.994
1513.4	421.632
1516.28	426.935
1519.15	449.128
1522.03	469.21
1524.91	500.291
1527.78	517.928
1530.65	553.232
1533.52	597.758
1536.39	670.617
1539.26	730.588
1542.12	820.669
1544.99	939.64
1547.85	1082.05
1550.71	1293.14
1553.57	1519.22
1556.43	1820.52
1559.29	2156.05
1562.14	2502.35
1565	2761.09
1567.85	2816.15
1570.7	2685.25
1573.55	2408.54
1576.39	2079.62
1579.24	1766.13
1582.08	1486.55
1584.93	1280.31
1587.77	1136.81
1590.61	1011.52
1593.44	936.615
1596.28	896.468
1599.12	891.347
1601.95	895.06
1604.78	905.359
1607.61	897.063
1610.44	817.616
1613.27	697.162
1616.09	590.173
1618.92	490.23
1621.74	421.174
1624.56	364.546
1627.38	325.347
1630.2	301.109
1633.02	281.076
1635.83	246.466
1638.13	236.651
1641.01	223.371
1643.9	209.757
1646.78	203.144
1649.65	193.197
1652.53	179.139
1655.41	181.415
1658.28	180.023
1661.16	173.632
1664.03	160.797
1666.9	162.85
1669.77	159.125
1672.63	156.956
1675.5	152.009
1678.36	144.396
1681.22	143.338
1684.09	146.614
1686.95	140.889
1689.8	137.275
1692.66	134.218
1695.52	135.16
1698.37	135.435
1701.22	134.155
1704.07	130.542
1706.92	136.261
1709.77	130.981
1712.62	132.368
1715.46	122.088
1718.3	128.363
1721.15	127.861
1723.99	117.025
1726.83	124.967
1729.66	121.798
1732.5	122.629
1735.33	120.905
1738.17	118.18
1741	119.678
1743.83	117.731
1746.66	119.673
1749.48	111.948
1752.31	114.002
1755.14	110.944
1757.96	115.219
1760.78	109.717
1763.6	105.326
1766.42	113.379
1769.24	114.654
1772.05	109.374
1774.87	104.761
1777.68	107.814
1780.49	108.423
1783.3	105.031
1786.11	109.529
1788.91	110.916
1791.72	108.302
1794.52	108.133
1797.33	104.964
1800.13	104.351
1802.93	111.071
1805.72	109.679
1808.52	99.6214
1811.32	105.786
1814.11	102.839
1816.9	104.337
1819.69	106.168
1822.48	102.887
1825.27	107.941
1828.06	108.327
1830.84	108.38
1833.62	107.656
1836.41	103.598
1839.19	104.873
1841.97	108.038
1844.74	108.091
1847.52	101.7
1850.29	112.42
1853.07	109.806
1855.84	107.526
1858.61	114.69
1861.38	111.632
1864.15	108.241
1866.91	112.072
1869.68	110.57
1872.44	112.845
1875.2	110.009
1877.96	112.396
1880.72	111.449
1883.48	112.614
1886.24	108.333
1888.99	105.164
1891.74	107.662
1894.5	103.715
1897.25	105.991
1899.99	103.933
1902.74	103.986
1905.49	102.706
1908.23	102.981
1910.98	100.701
1913.72	97.8655
1916.46	103.919
1919.2	103.305
1921.94	100.692
1924.67	97.1895
1927.4	99.576
1930.14	99.1848
1932.87	97.4602
1935.6	93.7357
1938.33	98.9
1941.06	100.842
1943.78	99.2286
1946.51	98.6152
1949.23	98.7795
1951.95	100.833
1954.67	98.3303
1957.39	96.3836
1960.11	99.659
1962.82	98.0455
1965.54	96.8765
1968.25	101.263
1970.96	96.6496
1973.67	96.8139
1976.38	100.423
1979.09	103.476
1981.8	97.6402
1984.5	97.0267
1987.2	98.8577
1989.9	98.4665
1992.61	98.9642
1995.3	97.4618
1998	99.4039
2000.7	103.679
2003.39	100.621
2006.08	102.008
2008.78	103.839
2011.47	96.2255
2014.16	101.723
2016.85	99.9986
2019.53	99.6074
2022.22	102.549
2024.9	100.936
2027.58	102.323
2030.26	99.1535
2032.94	97.8734
2035.62	99.8155
2038.29	99.7576
2040.97	100.922
2043.64	95.3085
2046.31	97.5839
2048.98	101.193
2051.65	100.468
2054.32	98.2991
2056.99	97.9078
2059.65	100.294
2062.32	92.3476
2064.98	99.4008
2067.64	98.6762
2070.3	91.9517
2072.96	93.6715
2075.61	94.3914
2078.27	96.6669
2080.92	92.4978
2083.57	92.5511
2086.23	93.2709
2088.88	93.4352
2091.52	91.8218
2094.17	92.4306
2096.81	91.8171
2099.46	88.3148
2102.1	92.0346
2104.74	91.9767
2107.38	93.0299
2110.02	95.3054
2112.66	99.2475
2115.29	91.634
2117.93	90.6872
2120.56	92.8515
2123.19	91.127
2125.82	90.958
2128.45	97.3445
2131.08	89.6199
2133.7	93.3398
2136.33	87.9486
2138.95	92.4462
2141.57	90.9439
2144.19	93.886
2146.81	90.9392
2149.43	93.2146
2152.04	92.1567
2154.66	88.9877
2157.27	94.5965
2159.89	90.983
2162.5	92.4807
2165.11	93.645
2167.71	93.5871
2170.32	90.6403
2172.92	96.4713
2175.53	91.3023
2178.13	93.1333
2180.73	89.742
2183.33	90.7952
2185.93	94.9595
2188.53	94.9016
2191.12	91.9548
2193.71	90.8722
2196.31	88.3659
2198.9	92.7513
2201.49	93.897
2204.08	94.3772
2206.66	93.2485
2209.25	90.411
2211.83	93.5213
2214.42	94.8228
2217	93.5712
2219.58	91.4105
2222.16	93.3348
2224.73	90.1964
2227.31	91.3659
2229.88	91.4108
2232.46	91.3151
2235.03	93.1957
2237.6	96.5036
2240.17	94.13
2242.74	91.4281
2245.3	92.9318
2247.87	91.7331
2250.43	92.0814
2253	93.3104
2255.56	88.7121
2258.12	96.6029
2260.67	92.3885
2262.71	93.0232
2265.34	97.6994
2267.96	98.0423
2270.58	96.7186
2273.2	97.3948
2275.82	99.4044
2278.44	96.9695
2281.05	100.757
2283.67	96.0997
2286.28	94.776
2288.89	98.6744
2291.5	96.0173
2294.11	99.4713
2296.72	98.4809
2299.33	98.7127
2301.93	104.5
2304.53	104.176
2307.14	97.0747
2309.74	104.306
2312.34	103.649
2314.94	103.77
2317.53	106.891
2320.13	106.345
2322.73	96.2432
2325.32	103.808
2327.91	111.929
2330.5	108.494
2333.09	107.17
2335.68	104.18
2338.26	108.189
2340.85	109.643
2343.43	111.542
2346.02	105.551
2348.6	106.783
2351.18	113.46
2353.76	110.358
2356.33	110.479
2358.91	110.155
2361.49	111.942
2364.06	109.618
2366.63	115.184
2369.2	114.526
2371.77	118.758
2374.34	119.434
2376.91	116.777
2379.47	119.676
2382.04	127.019
2384.6	120.251
2387.16	121.705
2389.72	128.27
2392.28	132.724
2394.84	134.178
2397.4	139.409
2399.95	137.975
2402.51	145.429
2405.06	149.66
2407.61	147.67
2410.16	157.124
2412.71	151.467
2415.26	168.81
2417.8	170.597
2420.35	177.384
2422.89	180.394
2425.43	189.292
2427.97	187.635
2430.51	191.2
2433.05	189.543
2435.59	194.553
2438.12	196.674
2440.66	195.683
2443.19	199.137
2445.72	188.813
2448.26	187.934
2450.78	183.388
2453.31	185.175
2455.84	175.074
2458.36	173.639
2460.89	173.649
2463.41	168.769
2465.93	169.334
2468.45	166.788
2470.97	161.353
2473.49	168.807
2476	169.706
2478.52	164.715
2481.03	158.169
2483.55	157.846
2486.06	159.633
2488.57	158.087
2491.07	156.874
2493.58	157.884
2496.09	155.116
2498.59	161.57
2501.1	161.802
2503.6	153.811
2506.1	149.487
2508.6	158.275
2511.1	154.395
2513.59	158.849
2516.09	157.859
2518.58	155.091
2521.08	155.989
2523.57	156.554
2526.06	162.786
2528.55	157.24
2531.04	161.472
2533.52	160.704
2536.01	159.269
2538.49	160.723
2540.98	165.066
2543.46	164.631
2545.94	167.196
2548.42	165.761
2550.89	170.437
2553.37	178.002
2555.85	176.679
2558.32	172.688
2560.79	176.253
2563.26	186.707
2565.73	182.161
2568.2	188.726
2570.67	191.514
2573.14	194.746
2575.6	197.866
2578.07	200.987
2580.53	198.219
2582.99	208.451
2585.45	215.127
2587.91	222.247
2590.36	223.146
2592.82	234.489
2595.27	240.276
2597.73	247.175
2600.18	254.962
2602.63	266.749
2605.08	284.759
2607.53	287.435
2609.98	298.667
2612.42	321.899
2614.87	326.464
2617.31	338.029
2619.75	360.816
2622.19	375.937
2624.63	403.169
2627.07	423.734
2629.51	456.188
2631.94	480.086
2634.38	509.54
2636.81	548.105
2639.24	577.337
2641.67	628.569
2644.1	676.912
2646.53	720.144
2648.96	763.264
2651.38	815.496
2653.81	873.283
2656.23	938.626
2658.65	1008.64
2661.07	1092.76
2663.49	1155.88
2665.91	1214.33
2668.33	1262.79
2670.74	1319.02
2673.16	1361.47
2675.57	1400.59
2677.98	1398.38
2680.39	1388.5
2682.8	1387.51
2685.21	1333.52
2687.62	1289.97
2690.02	1242.76
2692.43	1184.55
2694.83	1108.89
2697.23	1054.01
2699.63	969.91
2702.03	908.141
2704.43	843.484
2706.83	790.938
2709.22	739.615
2711.62	682.18
2714.01	627.189
2716.4	575.643
2718.79	540.986
2721.18	496.329
2723.57	474.561
2725.95	437.57
2728.34	411.135
2730.72	382.701
2733.11	351.488
2735.49	337.164
2737.87	328.174
2740.25	298.961
2742.63	289.304
2745	262.314
2747.38	259.656
2749.75	254.555
2752.13	243.342
2754.5	233.352
2756.87	229.917
2759.24	220.26
2761.6	210.825
2763.97	206.612
2766.34	200.066
2768.7	200.52
2771.06	194.42
2773.43	184.157
2775.79	180.644
2778.15	181.308
2780.51	176.292
2782.86	170.058
2785.22	169.044
2787.57	170.213
2789.93	172.694
2792.28	164.962
2794.63	158.657
2796.98	162.72
2799.32	163.271
2801.67	160.647
2804.02	155.256
2806.36	157.901
2808.71	154.943
2811.05	154.898
2813.39	155.396
2815.73	153.42
2818.07	153.895
2820.4	154.215
2822.74	151.121
2825.07	151.145
2827.41	151.551
2829.74	151.057
2831.81	143.651
2834.2	148.205
2836.6	147.092
2838.99	148.98
2841.38	144.2
2843.77	148.977
2846.16	152.42
2848.55	147.64
2850.94	148.972
2853.32	146.749
2855.71	149.636
2858.09	139.301
2860.48	141.633
2862.86	148.632
2865.24	148.297
2867.62	151.296
2869.99	147.85
2872.37	154.959
2874.74	149.958
2877.12	153.734
2879.49	155.733
2881.86	157.731
2884.23	161.174
2886.6	163.173
2888.97	166.394
2891.34	170.281
2893.7	169.835
2896.07	171.611
2898.43	174.388
2900.79	174.72
2903.15	174.385
2905.51	179.161
2907.87	172.604
2910.23	175.603
2912.58	177.046
2914.94	177.267
2917.29	181.71
2919.65	186.375
2922	182.484
2924.35	171.705
2926.7	171.37
2929.05	175.258
2931.39	175.701
2933.74	169.811
2936.08	174.809
2938.42	168.474
2940.77	164.028
2943.11	154.582
2945.45	158.692
2947.79	153.357
2950.12	151.356
2952.46	144.466
2954.79	141.464
2957.13	135.129
2959.46	137.795
2961.79	135.46
2964.12	136.014
2966.45	130.679
2968.78	123.344
2971.1	120.898
2973.43	123.341
2975.76	114.896
2978.08	115.894
2980.4	111.67
2982.72	109.669
2985.04	106.668
2987.36	105.777
2989.68	105.553
2991.99	105.441
2994.31	102.217
2996.62	101.216
2998.93	101.992
3001.25	100.657
3003.56	100.545
3005.87	99.9878
3008.17	98.5419
3010.48	95.096
3012.79	100.761
3015.09	95.3153
3017.39	90.6472
3019.7	96.4235
3022	97.7554
3024.3	90.754
3026.59	91.9747
3028.89	96.3066
3031.19	94.6385
3033.49	91.9704
3035.78	92.3023
3038.07	92.8564
3040.36	89.8549
3042.65	91.0757
3044.94	92.852
3047.23	92.9617
3049.52	89.1825
3051.8	90.5143
3054.09	88.5129
3056.37	94.7337
3058.65	85.6211
3060.94	87.3974
3063.22	87.1738
3065.49	85.3945
3067.77	85.7264
3070.05	88.6139
3072.32	86.6124
3074.6	87.4998
3076.87	84.9428
3079.14	86.9414
3081.42	86.3844
3083.68	88.2718
3085.95	91.2704
3088.22	86.8245
3090.49	86.0453
3092.75	89.7105
3095.02	85.3757
3097.28	89.2631
3099.54	90.9284
3101.8	90.9269
3104.06	89.9255
3106.32	89.924
3108.57	86.5892
3110.83	85.3655
3113.08	89.9196
3115.34	89.1404
3117.59	85.5834
3119.84	88.8042
3122.09	86.4694
3124.34	88.9124
3126.59	91.5776
3128.83	90.6873
3131.08	87.3525
3133.32	91.1288
3135.57	90.3496
3137.81	94.7926
3140.05	97.7911
3142.29	92.6786
3144.53	93.2327
3146.77	99.0206
3149	91.4869
3151.24	96.6198
3153.47	95.6415
3155.7	94.6633
3157.94	93.3518
3160.17	95.1513
3162.4	92.2842
3164.62	95.1949
3166.85	94.4389
3169.08	95.2384
3171.3	94.4825
3173.53	96.1709
3175.75	94.0816
3177.97	94.77
3180.19	95.4585
3182.41	95.9247
3184.63	97.2798
3186.84	92.9682
3189.06	98.8789
3191.27	104.345
3193.49	99.4781
3195.7	105.389
3197.91	109.299
3200.12	106.654
3202.33	115.898
3204.54	120.698
3206.74	126.942
3208.95	134.631
3211.15	139.097
3213.36	144.007
3215.56	139.363
3217.76	155.162
3219.96	150.517
3222.16	148.428
3224.36	152.783
3226.55	136.805
3228.75	134.049
3230.94	119.515
3233.13	117.759
3235.33	113.003
3237.52	105.803
3239.71	99.3799
3241.9	92.5128
3244.08	93.0901
3246.27	84.8897
3248.45	85.6892
3250.64	84.1555
3252.82	79.7328
3255	79.4212
3257.18	78.443
3259.36	78.7981
3261.54	75.1533
3263.72	74.5084
3265.9	77.3079
3268.07	72.4408
3270.24	73.4626
3272.42	72.1511
3274.59	74.7284
3276.76	73.4168
3278.93	69.7719
3281.1	74.1271
3283.26	75.4822
3285.43	72.8373
3287.59	73.4146
3289.76	68.3253
3291.92	71.6804
3294.08	69.0355
3296.24	72.2795
3298.4	73.3046
3300.56	71.095
3302.72	68.4352
3304.87	69.9102
3307.03	67.7903
3309.18	70.2059
3311.33	68.995
3313.48	70.9788
3315.63	70.0124
3317.78	70.7941
3319.93	68.6423
3322.08	67.9362
3324.22	67.5356
3326.37	70.7949
3328.51	69.709
3330.65	69.6112
3332.8	66.4409
3334.94	69.6086
3337.07	68.1389
3339.21	69.8078
3341.35	68.4364
3343.49	70.6007
3345.62	68.2714
3347.75	70.6675
3349.89	68.7382
3352.02	67.2981
3353.77	66.7992
3355.96	68.7955
3358.15	71.1252
3360.34	67.8993
3362.53	69.0067
3364.72	68.7808
3366.91	71.8882
3369.09	69.8846
3371.28	69.992
3373.46	68.655
3375.65	62.8735
3377.83	72.7587
3380.01	70.9773
3382.19	71.5292
3384.37	67.9699
3386.54	69.1885
3388.72	71.2959
3390.89	69.4034
3393.07	69.1774
3395.24	69.9516
3397.41	66.059
3399.58	68.4997
3401.75	73.4961
3403.92	68.1591
3406.09	69.0443
3408.26	68.5962
3410.42	70.148
3412.59	65.811
3414.75	69.1407
3416.91	68.2481
3419.07	69.5778
3421.23	70.6852
3423.39	70.0149
3425.55	71.3445
3427.71	69.0075
3429.86	71.7816
3432.02	66.889
3434.17	69.7742
3436.32	68.5484
3438.48	69.2113
3440.63	68.7632
3442.78	66.5373
3444.92	68.867
3447.07	66.53
3449.22	68.6374
3451.36	65.7448
3453.51	67.0745
3455.65	69.4041
3457.79	66.6227
3459.93	64.9523
3462.07	68.282
3464.21	67.1672
3466.35	70.608
3468.49	64.6043
3470.62	65.2673
3472.76	66.0414
3474.89	67.0377
3477.02	65.7007
3479.15	68.1415
3481.28	66.4711
3483.41	65.023
3485.54	66.7971
3487.67	66.6823
3489.79	66.3453
3491.92	66.8972
3494.04	67.8935
3496.17	69.3343
3498.29	68.775
3499.88	68.8834