File: Notebooks/Exercise data/Oxidised MWCNTs_1.txt
#Acq. time (s)=	3
#Accumulations=	10
#Range (cm-¹)=	100...3500
#Windows=	6
#Autofocus=	Off
#AutoExposure=	Off
#Spike filter=	Multiple accum.
#Delay time (s)=	0
#Binning=	1
#Readout mode=	Signal
#DeNoise=	Off
#ICS correction=	Off
#Dark correction=	Off
#Inst. Process=	Off
#Instrument=	ARAMIS
#Detector=	Andor CCD
#Objective=	x50 SLWD
#Grating=	1800
#Filter=	100%
#Laser (nm)=	532
#Slit=	150
#Hole=	400
#Location=	Micro
#Range=	VIS
#StageXY=	Marzhauser
#StageZ=	Marzhauser
#X (µm)=	-7965.4
#Y (µm)=	-9947.55
#Z (µm)=	519.45
#Project=
#Sample=
#Site=
#Title=	Oxidised MWCNTs 30_1
#Remark=
#Date=	06.03.2020 12:24
#Acquired=	06.03.2020 12:24:08
100.291	292.778
103.86	318.766
107.427	307.198
110.993	324.742
114.556	340.396
118.119	327.607
121.679	334.817
125.235	313.694
128.793	323.904
132.346	343.336
135.899	294.102
139.45	271.646
142.997	271.411
146.543	270.733
150.088	277.498
153.632	266.598
157.172	266.586
160.71	270.24
164.247	256.228
167.783	264.105
171.316	257.204
174.847	252.97
178.377	253.513
181.903	254.724
185.428	251.934
188.952	253.811
192.474	253.576
195.993	241.231
199.511	245.441
203.027	247.874
206.542	242.751
210.054	245.961
213.564	242.504
217.073	238.048
220.58	240.814
224.084	234.468
227.587	242.456
231.086	236.889
234.586	242.432
238.083	244.531
241.579	242.186
245.071	244.841
248.563	247.718
252.053	239.706
255.541	241.582
259.025	250.682
262.509	248.558
265.991	248.102
269.471	245.757
272.949	247.411
276.427	241.955
279.899	248.054
283.373	245.486
286.843	241.808
290.311	243.573
293.779	245.228
297.243	245.66
300.707	238.871
304.169	244.081
307.627	239.18
311.086	240.946
314.541	236.045
317.993	239.588
321.446	242.132
324.896	233.787
328.344	234.219
331.791	237.207
335.234	227.084
338.676	227.516
342.117	222.171
345.557	235.048
348.993	229.036
352.428	226.246
355.862	238.678
359.293	224.555
362.722	220.099
366.15	225.865
369.576	226.742
373	231.396
376.422	233.94
379.842	216.594
383.26	234.249
386.676	228.348
390.091	229.336
393.504	228.213
396.914	225.423
400.323	231.522
403.731	224.066
407.135	228.943
410.538	228.708
413.94	225.474
417.341	238.684
420.738	232.783
424.134	236.883
427.529	232.759
430.92	224.303
434.311	230.513
437.7	229.168
441.087	239.6
444.472	230.144
447.855	234.021
451.237	231.564
454.615	240.108
457.993	231.54
461.369	234.195
464.744	233.961
468.115	223.504
471.486	230.603
474.855	228.258
478.221	221.468
481.585	221.345
484.948	219.333
488.309	223.765
491.669	225.531
495.027	217.63
498.381	216.285
501.736	219.495
505.088	219.15
508.437	220.249
511.786	222.792
515.133	214.558
518.477	222.213
521.819	225.867
525.161	226.3
528.501	226.843
531.837	230.831
535.173	233.486
538.507	241.474
541.839	243.684
545.168	240.117
548.496	250.882
551.823	255.093
555.148	248.303
558.47	250.624
561.791	250.723
565.111	250.156
568.428	243.033
571.743	243.576
575.057	244.231
578.37	239.663
581.68	236.54
584.988	239.084
588.293	236.849
591.599	237.726
594.902	232.048
598.202	226.813
601.502	222.357
604.799	226.123
608.096	222.888
611.388	213.432
614.68	220.198
617.97	213.519
621.26	208.618
624.546	203.939
627.831	203.15
631.114	203.804
634.395	204.237
637.674	193.669
640.952	198.768
644.229	192.312
647.503	194.189
650.775	195.066
654.045	189.054
657.313	186.597
660.58	189.03
663.846	185.351
667.108	185.117
670.37	175.66
673.63	179.648
676.887	169.969
680.145	172.069
683.398	177.168
686.651	162.489
689.902	165.588
693.151	160.687
696.399	162.786
699.644	156.774
702.888	160.762
706.129	158.306
709.37	155.294
712.608	155.726
715.843	155.825
719.079	151.813
722.312	149.468
725.544	148.678
728.772	147.999
732	147.876
735.226	152.642
738.451	146.074
741.673	151.84
744.894	145.495
748.111	148.372
751.33	152.471
754.545	142.57
757.757	144.336
760.97	153.657
764.18	147.978
767.387	144.855
770.595	152.177
773.799	148.387
777.003	148.486
780.203	151.474
783.402	150.906
786.6	151.783
789.797	147.438
792.991	152.426
796.183	148.192
799.373	141.18
802.563	145.612
805.75	144.822
808.934	145.921
812.117	140.798
815.299	138.786
818.48	143.552
821.658	137.207
824.834	139.75
828.01	138.516
831.184	134.17
834.355	130.492
837.523	135.146
840.692	133.579
843.858	131.678
847.023	125.777
850.184	135.098
853.345	132.197
856.504	127.741
859.663	138.173
862.818	129.606
865.972	126.149
869.123	132.862
872.273	128.576
875.422	128.996
878.57	129.124
881.715	125.633
884.858	128.208
888.001	126.282
891.14	126.385
894.278	125.725
897.416	126.451
900.55	130.577
903.683	128.25
906.815	130.727
909.944	130.28
913.072	136.476
916.198	136.04
919.322	134.879
922.445	141.362
925.566	139.706
928.685	140.93
931.802	147.684
934.918	146.263
938.032	154.223
941.144	156.206
944.255	156.504
947.365	154.716
950.025	155.763
953.207	161.031
956.383	155.966
959.561	159.234
962.736	157.391
965.909	158.771
969.081	161.595
972.251	165.307
975.419	173.464
978.586	175.177
981.752	177.223
984.914	182.713
988.076	180.093
991.237	185.472
994.394	185.518
997.553	182.009
1000.71	181.721
1003.86	186.878
1007.01	186.147
1010.16	183.971
1013.31	190.017
1016.46	200.729
1019.6	197.442
1022.75	199.155
1025.89	209.423
1029.03	213.691
1032.17	213.404
1035.3	223.339
1038.44	221.718
1041.57	230.208
1044.7	236.032
1047.83	238.634
1050.96	247.791
1054.09	261.281
1057.21	263.772
1060.34	265.818
1063.46	273.086
1066.58	283.799
1069.7	286.4
1072.81	295.335
1075.93	299.27
1079.04	309.872
1082.15	313.14
1085.26	322.853
1088.37	321.677
1091.48	329.167
1094.59	336.324
1097.69	325.37
1100.79	321.416
1103.89	318.129
1106.99	311.286
1110.09	313.554
1113.18	298.822
1116.28	303.313
1119.37	291.137
1122.46	280.849
1125.55	275.451
1128.64	267.053
1131.72	261.654
1134.81	264.478
1137.89	252.635
1140.97	245.459
1144.05	232.283
1147.13	232.551
1150.2	238.152
1153.28	228.198
1156.35	225.911
1159.42	220.068
1162.49	221.892
1165.56	221.494
1168.62	213.762
1171.69	212.919
1174.75	211.854
1177.81	205.9
1180.87	198.39
1183.93	189.881
1186.99	197.816
1190.04	198.64
1193.09	196.686
1196.14	189.843
1199.19	191.333
1202.24	182.713
1205.29	191.759
1208.33	191.249
1211.38	185.184
1214.42	192.674
1217.46	188.387
1220.5	190.655
1223.53	189.257
1226.57	187.858
1229.6	193.793
1232.63	195.617
1235.67	197.552
1238.69	196.598
1241.72	200.644
1244.75	200.579
1247.77	205.625
1250.79	205.56
1253.81	210.495
1256.83	208.096
1259.85	214.809
1262.87	216.633
1265.88	223.457
1268.89	230.28
1271.9	229.882
1274.91	238.15
1277.92	244.974
1280.93	251.465
1283.93	255.733
1286.93	256.89
1289.94	268.38
1292.94	283.76
1295.93	291.361
1298.93	302.852
1301.93	322.564
1304.92	343.166
1307.91	370.323
1310.9	399.258
1313.89	441.749
1316.88	469.239
1319.86	514.174
1322.85	580.109
1325.83	636.155
1328.81	729.312
1331.79	802.691
1334.76	889.626
1337.74	959.339
1340.71	1001.83
1343.69	1010.54
1346.66	971.81
1349.63	907.967
1352.6	841.013
1355.56	768.393
1358.53	680.55
1361.49	609.818
1364.45	550.864
1367.41	501.688
1370.37	458.401
1373.33	409.558
1376.28	380.826
1379.23	351.428
1382.19	331.696
1385.14	323.742
1388.09	300.455
1391.03	286.278
1393.98	275.991
1396.92	266.481
1399.87	257.083
1402.81	254.018
1405.75	247.731
1408.68	248.999
1411.62	243.934
1414.55	233.091
1417.49	242.137
1420.42	226.85
1423.35	225.118
1426.28	226.608
1429.2	221.321
1432.13	224.923
1435.05	219.746
1437.97	215.57
1440.89	219.95
1443.81	210.218
1446.73	220.708
1449.65	213.643
1452.56	215.023
1455.47	221.069
1458.38	222.003
1461.29	219.161
1464.2	220.318
1467.11	224.586
1470.01	213.521
1472.92	226.011
1475.82	222.724
1478.72	224.103
1481.62	226.594
1484.51	229.862
1487.41	226.241
1490.3	226.176
1493.19	232
1496.08	243.379
1498.97	232.648
1501.86	244.694
1504.75	246.406
1507.63	246.786
1510.52	250.832
1513.4	248.878
1516.28	264.146
1519.15	267.637
1522.03	274.905
1524.91	284.284
1527.78	301.552
1530.65	322.043
1533.52	331.755
1536.39	355.69
1539.26	377.07
1542.12	419.671
1544.99	458.828
1547.85	511.874
1550.71	595.809
1553.57	682.189
1556.43	791.124
1559.29	931.836
1562.14	1105.66
1565	1308.88
1567.85	1472.06
1570.7	1590.7
1573.55	1614.44
1576.39	1562.22
1579.24	1420.43
1582.08	1237.23
1584.93	1062.53
1587.77	915.81
1590.61	791.629
1593.44	696.036
1596.28	629.51
1599.12	574.04
1601.95	556.481
1604.78	547.602
1607.61	553.95
1610.44	552.88
1613.27	550.87
1616.09	515.096
1618.92	461.56
1621.74	402.788
1624.56	340.916
1627.38	305.944
1630.2	271.548
1633.02	244.875
1635.83	229.036
1638.13	220.248
1641.01	209.149
1643.9	201.05
1646.78	189.506
1649.65	187.296
1652.53	180.975
1655.41	175.542
1658.28	171.554
1661.16	162.566
1664.03	164.134
1666.9	157.701
1669.77	160.269
1672.63	156.837
1675.5	151.849
1678.36	150.972
1681.22	152.65
1684.09	147.662
1686.95	147.008
1689.8	143.575
1692.66	143.81
1695.52	143.044
1698.37	145.167
1701.22	144.735
1704.07	136.635
1706.92	150.759
1709.77	141.215
1712.62	133.783
1715.46	140.906
1718.3	136.918
1721.15	137.819
1723.99	140.275
1726.83	131.509
1729.66	139.077
1732.5	131.422
1735.33	134.99
1738.17	130.335
1741	133.014
1743.83	133.693
1746.66	134.149
1749.48	133.605
1752.31	132.729
1755.14	130.852
1757.96	133.975
1760.78	132.098
1763.6	133.443
1766.42	128.566
1769.24	128.912
1772.05	131.368
1774.87	126.047
1777.68	129.059
1780.49	122.849
1783.3	129.083
1786.11	122.651
1788.91	128.218
1791.72	129.119
1794.52	127.464
1797.33	125.365
1800.13	127.822
1802.93	123.834
1805.72	124.735
1808.52	124.413
1811.32	125.425
1814.11	121.549
1816.9	126.005
1819.69	120.35
1822.48	131.029
1825.27	128.597
1828.06	124.72
1830.84	122.954
1833.62	124.744
1836.41	126.756
1839.19	124.101
1841.97	125.446
1844.74	130.236
1847.52	127.471
1850.29	119.594
1853.07	128.606
1855.84	123.618
1858.61	120.963
1861.38	131.308
1864.15	126.765
1866.91	129.555
1869.68	131.122
1872.44	125.134
1875.2	128.368
1877.96	128.936
1880.72	131.837
1883.48	128.627
1886.24	124.75
1888.99	127.54
1891.74	126.329
1894.5	126.119
1897.25	119.02
1899.99	126.81
1902.74	124.933
1905.49	122.39
1908.23	122.846
1910.98	123.08
1913.72	121.87
1916.46	122.549
1919.2	122.672
1921.94	126.128
1924.67	120.363
1927.4	115.597
1930.14	124.164
1932.87	121.621
1935.6	118.966
1938.33	121.2
1941.06	116.212
1943.78	116.78
1946.51	118.348
1949.23	121.693
1951.95	121.038
1954.67	117.939
1957.39	119.173
1960.11	118.741
1962.82	125.642
1965.54	117.543
1968.25	116.999
1970.96	118.567
1973.67	117.245
1976.38	121.591
1979.09	117.27
1981.8	121.726
1984.5	118.405
1987.2	120.75
1989.9	122.206
1992.61	117.996
1995.3	120.342
1998	120.909
2000.7	121.366
2003.39	126.267
2006.08	117.39
2008.78	125.735
2011.47	121.525
2014.16	118.981
2016.85	117.438
2019.53	119.116
2022.22	121.462
2024.9	125.696
2027.58	129.93
2030.26	116.942
2032.94	120.621
2035.62	121.855
2038.29	120.534
2040.97	117.768
2043.64	125.447
2046.31	122.348
2048.98	119.582
2051.65	119.038
2054.32	115.273
2056.99	115.396
2059.65	115.963
2062.32	116.198
2064.98	120.765
2067.64	118.222
2070.3	118.678
2072.96	115.246
2075.61	118.035
2078.27	114.714
2080.92	120.504
2083.57	114.294
2086.23	114.084
2088.88	116.651
2091.52	115.774
2094.17	113.675
2096.81	115.354
2099.46	119.255
2102.1	118.267
2104.74	117.168
2107.38	115.291
2110.02	117.636
2112.66	117.537
2115.29	117.549
2117.93	115.006
2120.56	115.129
2123.19	123.474
2125.82	113.708
2128.45	114.165
2131.08	114.954
2133.7	114.633
2136.33	112.423
2138.95	116.435
2141.57	115.447
2144.19	116.57
2146.81	113.471
2149.43	115.261
2152.04	118.828
2154.66	116.174
2157.27	117.852
2159.89	116.531
2162.5	114.654
2165.11	114.555
2167.71	117.012
2170.32	114.135
2172.92	109.369
2175.53	114.492
2178.13	113.726
2180.73	112.294
2183.33	107.75
2185.93	116.429
2188.53	116.108
2191.12	114.564
2193.71	112.015
2196.31	121.29
2198.9	115.36
2201.49	116.9
2204.08	116.039
2206.66	115.031
2209.25	116.383
2211.83	112.703
2214.42	114.068
2217	113.44
2219.58	114.502
2222.16	114.571
2224.73	111.782
2227.31	112.916
2229.88	114.844
2232.46	113.409
2235.03	114.593
2237.6	111.444
2240.17	111.503
2242.74	116.606
2245.3	116.891
2247.87	114.037
2250.43	115.101
2253	114.522
2255.56	116.348
2258.12	120.621
2260.67	111.297
2262.71	118.114
2265.34	119.359
2267.96	114.271
2270.58	118.961
2273.2	117.54
2275.82	119.452
2278.44	116.031
2281.05	122.054
2283.67	118.189
2286.28	116.434
2288.89	121.902
2291.5	118.925
2294.11	118.837
2296.72	119.971
2299.33	123.772
2301.93	119.129
2304.53	119.375
2307.14	120.731
2309.74	122.643
2312.34	122.333
2314.94	125.134
2317.53	119.602
2320.13	122.625
2322.73	122.759
2325.32	131.338
2327.91	141.028
2330.5	135.718
2333.09	127.63
2335.68	131.876
2338.26	130.343
2340.85	133.478
2343.43	133.612
2346.02	134.635
2348.6	132.77
2351.18	134.571
2353.76	139.261
2356.33	139.617
2358.91	137.974
2361.49	137.552
2364.06	146.909
2366.63	145.043
2369.2	152.844
2371.77	156.868
2374.34	151.335
2376.91	152.692
2379.47	155.493
2382.04	151.738
2384.6	157.317
2387.16	154.785
2389.72	157.697
2392.28	158.387
2394.84	162.077
2397.4	168.656
2399.95	161.79
2402.51	165.48
2405.06	171.948
2407.61	167.526
2410.16	170.772
2412.71	182.128
2415.26	174.596
2417.8	180.508
2420.35	183.309
2422.89	191.888
2425.43	190.133
2427.97	200.934
2430.51	193.958
2433.05	200.759
2435.59	202.893
2438.12	204.027
2440.66	200.384
2443.19	203.852
2445.72	200.542
2448.26	203.009
2450.78	195.255
2453.31	197.056
2455.84	196.635
2458.36	196.769
2460.89	197.348
2463.41	190.149
2465.93	192.061
2468.45	191.529
2470.97	184.885
2473.49	184.019
2476	183.487
2478.52	189.177
2481.03	183.423
2483.55	179.779
2486.06	171.691
2488.57	174.937
2491.07	171.182
2493.58	177.872
2496.09	177.895
2498.59	177.363
2501.1	175.608
2503.6	178.409
2506.1	173.322
2508.6	172.9
2511.1	177.146
2513.59	176.725
2516.09	169.303
2518.58	175.993
2521.08	174.128
2523.57	171.373
2526.06	169.508
2528.55	185.864
2531.04	176.332
2533.52	176.688
2536.01	178.156
2538.49	178.735
2540.98	169.425
2543.46	173.337
2545.94	170.36
2548.42	180.383
2550.89	176.851
2553.37	170.43
2555.85	175.453
2558.32	181.143
2560.79	176.611
2563.26	178.523
2565.73	186.324
2568.2	188.236
2570.67	193.593
2573.14	182.616
2575.6	186.639
2578.07	184.551
2580.53	191.463
2582.99	189.264
2585.45	193.954
2587.91	205.2
2590.36	201.001
2592.82	204.024
2595.27	207.047
2597.73	208.959
2600.18	204.205
2602.63	213.45
2605.08	218.362
2607.53	224.83
2609.98	232.631
2612.42	242.099
2614.87	248.789
2617.31	253.256
2619.75	253.835
2622.19	268.081
2624.63	270.437
2627.07	293.349
2629.51	291.484
2631.94	307.396
2634.38	316.863
2636.81	340.553
2639.24	365.354
2641.67	374.6
2644.1	408.068
2646.53	422.424
2648.96	448.447
2651.38	470.137
2653.81	501.16
2656.23	535.295
2658.65	565.096
2661.07	594.675
2663.49	631.587
2665.91	676.832
2668.33	734.855
2670.74	765.212
2673.16	796.791
2675.57	848.481
2677.98	868.06
2680.39	905.638
2682.8	909.328
2685.21	928.796
2687.62	922.93
2690.02	912.731
2692.43	888.31
2694.83	880.556
2697.23	811.912
2699.63	779.491
2702.03	743.736
2704.43	707.426
2706.83	661.672
2709.22	620.695
2711.62	573.163
2714.01	551.297
2716.4	495.654
2718.79	464.677
2721.18	439.589
2723.57	413.39
2725.95	390.191
2728.34	366.77
2730.72	338.571
2733.11	328.705
2735.49	308.728
2737.87	295.863
2740.25	278.33
2742.63	257.243
2745	254.488
2747.38	244.622
2749.75	233.312
2752.13	221.336
2754.5	215.692
2756.87	218.271
2759.24	209.627
2761.6	207.54
2763.97	201.341
2766.34	199.142
2768.7	189.387
2771.06	189.049
2773.43	186.493
2775.79	183.3
2778.15	184.024
2780.51	177.435
2782.86	173.543
2785.22	173.442
2787.57	169.497
2789.93	171.287
2792.28	176.8
2794.63	170.36
2796.98	167.828
2799.32	168.007
2801.67	165.816
2804.02	164.305
2806.36	161.121
2808.71	165.326
2811.05	164.517
2813.39	161.823
2815.73	162.024
2818.07	162.266
2820.4	163.147
2822.74	161.065
2825.07	162.095
2827.41	157.941
2829.74	160.133
2831.81	153.082
2834.2	167.528
2836.6	160.753
2838.99	156.977
2841.38	154.535
2843.77	157.092
2846.16	160.205
2848.55	157.763
2850.94	160.098
2853.32	160.322
2855.71	156.547
2858.09	162.66
2860.48	156.884
2862.86	159.108
2865.24	155.666
2867.62	157.557
2869.99	157.781
2872.37	160.005
2874.74	155.896
2877.12	156.565
2879.49	159.345
2881.86	157.236
2884.23	160.46
2886.6	168.907
2888.97	168.464
2891.34	168.911
2893.7	176.024
2896.07	171.026
2898.43	163.139
2900.79	172.03
2903.15	177.365
2905.51	170.145
2907.87	177.814
2910.23	180.594
2912.58	180.707
2914.94	182.264
2917.29	180.822
2919.65	180.491
2922	176.27
2924.35	181.05
2926.7	187.83
2929.05	179.277
2931.39	183.723
2933.74	183.281
2936.08	181.172
2938.42	183.062
2940.77	176.176
2943.11	176.622
2945.45	178.291
2947.79	171.515
2950.12	172.517
2952.46	167.63
2954.79	165.854
2957.13	168.412
2959.46	160.747
2961.79	165.861
2964.12	158.085
2966.45	154.531
2968.78	146.978
2971.1	154.202
2973.43	145.204
2975.76	142.095
2978.08	137.764
2980.4	141.321
2982.72	137.768
2985.04	138.659
2987.36	140.55
2989.68	135.996
2991.99	130.665
2994.31	129.334
2996.62	132.558
2998.93	129.115
3001.25	128.34
3003.56	130.675
3005.87	123.121
3008.17	127.124
3010.48	125.014
3012.79	123.016
3015.09	127.241
3017.39	122.909
3019.7	123.911
3022	125.913
3024.3	121.916
3026.59	125.029
3028.89	120.475
3031.19	125.588
3033.49	119.924
3035.78	123.815
3038.07	120.483
3040.36	115.819
3042.65	124.043
3044.94	122.489
3047.23	120.491
3049.52	117.938
3051.8	124.94
3054.09	119.386
3056.37	121.055
3058.65	117.724
3060.94	123.726
3063.22	122.617
3065.49	123.841
3067.77	115.954
3070.05	122.512
3072.32	121.847
3074.6	117.96
3076.87	120.74
3079.14	118.076
3081.42	118.3
3083.68	118.524
3085.95	120.526
3088.22	121.195
3090.49	113.197
3092.75	116.532
3095.02	122.312
3097.28	114.647
3099.54	115.316
3101.8	113.207
3104.06	120.32
3106.32	118.1
3108.57	113.769
3110.83	118.993
3113.08	120.662
3115.34	116.219
3117.59	120.888
3119.84	123.112
3122.09	115.336
3124.34	115.45
3126.59	119.007
3128.83	123.787
3131.08	125.456
3133.32	121.569
3135.57	120.682
3137.81	123.906
3140.05	128.13
3142.29	126.91
3144.53	121.468
3146.77	122.167
3149	122.007
3151.24	121.403
3153.47	128.022
3155.7	127.973
3157.94	124.814
3160.17	125.765
3162.4	123.717
3164.62	123.668
3166.85	127.175
3169.08	124.571
3171.3	123.301
3173.53	125.252
3175.75	127.426
3177.97	121.377
3180.19	125.218
3182.41	127.725
3184.63	125.232
3186.84	130.85
3189.06	127.691
3191.27	129.531
3193.49	127.594
3195.7	130.545
3197.91	133.386
3200.12	134.337
3202.33	131.4
3204.54	131.018
3206.74	136.859
3208.95	140.366
3211.15	143.873
3213.36	145.713
3215.56	149.776
3217.76	150.616
3219.96	154.235
3222.16	154.186
3224.36	161.138
3226.55	161.645
3228.75	162.707
3230.94	168.103
3233.13	159.388
3235.33	154.118
3237.52	153.625
3239.71	150.798
3241.9	136.083
3244.08	136.479
3246.27	136.764
3248.45	133.382
3250.64	133.778
3252.82	125.063
3255	128.126
3257.18	123.744
3259.36	126.696
3261.54	120.647
3263.72	121.043
3265.9	118.217
3268.07	113.057
3270.24	120.231
3272.42	114.072
3274.59	113.69
3276.76	112.753
3278.93	113.26
3281.1	111.989
3283.26	118.496
3285.43	113.336
3287.59	114.732
3289.76	114.351
3291.92	110.191
3294.08	109.587
3296.24	111.872
3298.4	118.617
3300.56	111.983
3302.72	114.973
3304.87	117.412
3307.03	112.756
3309.18	112.872
3311.33	115.196
3313.48	110.614
3315.63	109.093
3317.78	111.612
3319.93	113.501
3322.08	112.195
3324.22	113.442
3326.37	109.866
3328.51	112.785
3330.65	113.983
3332.8	112.334
3334.94	113.345
3337.07	112.954
3339.21	113.67
3341.35	112.863
3343.49	113.067
3345.62	111.831
3347.75	112.63
3349.89	115.756
3352.02	113.98
3353.77	115.618
3355.96	115.386
3358.15	111.489
3360.34	113.48
3362.53	117.138
3364.72	111.907
3366.91	118.12
3369.09	120.444
3371.28	115.991
3373.46	116.427
3375.65	114.973
3377.83	112.853
3380.01	115.289
3382.19	116.391
3384.37	111.716
3386.54	120.596
3388.72	111.92
3390.89	115.8
3393.07	122.013
3395.24	115.227
3397.41	118.107
3399.58	119.431
3401.75	116.2
3403.92	117.525
3406.09	114.405
3408.26	119.063
3410.42	115.831
3412.59	110.045
3414.75	119.591
3416.91	117.027
3419.07	114.574
3421.23	117.343
3423.39	118.556
3425.55	117.769
3427.71	118.427
3429.86	112.752
3432.02	114.409
3434.17	116.956
3436.32	113.947
3438.48	113.827
3440.63	115.041
3442.78	116.698
3444.92	115.801
3447.07	109.681
3449.22	118.672
3451.36	115.885
3453.51	114.876
3455.65	111.09
3457.79	112.081
3459.93	117.739
3462.07	110.508
3464.21	115.832
3466.35	115.823
3468.49	117.814
3470.62	109.361
3472.76	116.797
3474.89	114.121
3477.02	115.445
3479.15	117.659
3481.28	119.65
3483.41	112.197
3485.54	118.077
3487.67	110.623
3489.79	113.059
3491.92	118.494
3494.04	113.819
3496.17	119.366
3498.29	118.579
3499.88	111.017