File: Notebooks/Exercise data/Oxidised MWCNTs_2.txt
#Acq. time (s)=	3
#Accumulations=	10
#Range (cm-¹)=	100...3500
#Windows=	6
#Autofocus=	Off
#AutoExposure=	Off
#Spike filter=	Multiple accum.
#Delay time (s)=	0
#Binning=	1
#Readout mode=	Signal
#DeNoise=	Off
#ICS correction=	Off
#Dark correction=	Off
#Inst. Process=	Off
#Instrument=	ARAMIS
#Detector=	Andor CCD
#Objective=	x50 SLWD
#Grating=	1800
#Filter=	100%
#Laser (nm)=	532
#Slit=	150
#Hole=	400
#Location=	Micro
#Range=	VIS
#StageXY=	Marzhauser
#StageZ=	Marzhauser
#X (µm)=	-7075
#Y (µm)=	-11616.5
#Z (µm)=	507.4
#Project=
#Sample=
#Site=
#Title=	Oxidised MWCNTs 30_2
#Remark=
#Date=	06.03.2020 12:28
#Acquired=	06.03.2020 12:28:51
100.291	252.222
103.86	259.878
107.427	259.867
110.993	274.522
114.556	280.4
118.119	265.389
121.679	253.711
125.235	240.144
128.793	248.133
132.346	269.455
135.899	221.778
139.45	206.878
142.997	198.978
146.543	206.411
150.088	204.955
153.632	212.278
157.172	201.489
160.71	207.922
164.247	198.578
167.783	197.122
171.316	197.333
174.847	195.989
178.377	191.533
181.903	191.411
185.428	192.622
188.952	187.5
192.474	185.155
195.993	188.255
199.511	188.578
203.027	181.455
206.542	187.555
210.054	181.1
213.564	183.978
217.073	183.966
220.58	187.955
224.084	181.833
227.587	183.711
231.086	187.589
234.586	186.244
238.083	190.455
241.579	181
245.071	182.989
248.563	188.2
252.053	192.189
255.541	185.511
259.025	184.611
262.509	184.822
265.991	184.255
269.471	193.244
272.949	184.122
276.427	182.111
279.899	191.211
283.373	181.088
286.843	190.411
290.311	190.4
293.779	186.722
297.243	176.933
300.707	179.366
304.169	179.355
307.627	176.9
311.086	176.222
314.541	173.766
317.993	178.755
321.446	170.744
324.896	167.955
328.344	170.277
331.791	171.711
335.234	174.033
338.676	170.244
342.117	170.788
345.557	168.333
348.993	161.766
352.428	159.866
355.862	162.744
359.293	164.733
362.722	164.944
366.15	153.266
369.576	158.588
373	157.688
376.422	155.788
379.842	159.666
383.26	155.21
386.676	159.755
390.091	158.744
393.504	164.399
396.914	153.61
400.323	162.155
403.731	159.366
407.135	160.577
410.538	157.01
413.94	158.999
417.341	167.21
420.738	168.533
424.134	165.744
427.529	165.844
430.92	170.388
434.311	164.266
437.7	166.144
441.087	156.244
444.472	161.232
447.855	163.11
451.237	162.988
454.615	161.088
457.993	155.077
461.369	157.288
464.744	158.277
468.115	156.044
471.486	159.032
474.855	158.132
478.221	158.677
481.585	155.11
484.948	156.21
488.309	161.421
491.669	155.521
495.027	151.288
498.381	153.388
501.736	149.599
505.088	150.032
508.437	146.466
511.786	146.788
515.133	150.11
518.477	148.432
521.819	151.977
525.161	150.966
528.501	151.177
531.837	157.054
535.173	155.599
538.507	155.477
541.839	159.243
545.168	162.566
548.496	162.221
551.823	160.21
555.148	163.643
558.47	163.299
561.791	160.399
565.111	157.277
568.428	157.821
571.743	165.588
575.057	160.465
578.37	156.232
581.68	157.443
584.988	153.099
588.293	156.088
591.599	157.077
594.902	154.51
598.202	150.165
601.502	161.71
604.799	149.365
608.096	151.132
611.388	151.232
614.68	152.554
617.97	147.432
621.26	145.532
624.546	148.965
627.831	148.065
631.114	142.499
634.395	144.488
637.674	144.81
640.952	138.132
644.229	140.343
647.503	138.665
650.775	142.876
654.045	139.865
657.313	137.521
660.58	131.732
663.846	135.943
667.108	133.376
670.37	133.143
673.63	137.799
676.887	135.565
680.145	131.887
683.398	125.321
686.651	125.087
689.902	126.299
693.151	130.176
696.399	122.499
699.644	121.043
702.888	131.032
706.129	121.798
709.37	119.454
712.608	119.665
715.843	119.765
719.079	123.532
722.312	124.298
725.544	119.843
728.772	122.054
732	123.265
735.226	118.143
738.451	122.687
741.673	117.232
744.894	122.332
748.111	113.654
751.33	118.532
754.545	118.521
757.757	122.287
760.97	115.832
764.18	114.598
767.387	122.365
770.595	119.465
773.799	121.676
777.003	115.221
780.203	116.432
783.402	117.643
786.6	124.854
789.797	116.509
792.991	116.054
796.183	114.043
799.373	115.476
802.563	111.132
805.75	110.12
808.934	109.887
812.117	114.432
815.299	116.532
818.48	115.52
821.658	115.954
824.834	111.943
828.01	112.043
831.184	113.476
834.355	109.243
837.523	110.231
840.692	108.887
843.858	116.765
847.023	108.309
850.184	113.854
853.345	112.065
856.504	112.498
859.663	108.154
862.818	115.254
865.972	106.798
869.123	105.647
872.273	106.661
875.422	107.852
878.57	108.397
881.715	103.892
884.858	108.623
888.001	108.964
891.14	107.167
894.278	106.31
897.416	106.471
900.55	109.338
903.683	109.035
906.815	111.736
909.944	112.775
913.072	112.221
916.198	115.613
919.322	113.446
922.445	117.656
925.566	117.253
928.685	119.519
931.802	121.717
934.918	118.708
938.032	121.143
941.144	125.701
944.255	126.452
947.365	124.207
950.025	131.345
953.207	130.247
956.383	133.15
959.561	124.941
962.736	128.066
965.909	123.413
969.081	131.982
972.251	134.551
975.419	135.565
978.586	135.911
981.752	139.036
984.914	142.716
988.076	145.952
991.237	149.744
994.394	144.757
997.553	143.437
1000.71	140.451
1003.86	146.354
1007.01	143.478
1010.16	153.381
1013.31	143.95
1016.46	156.852
1019.6	160.421
1022.75	158.657
1025.89	159.226
1029.03	163.795
1032.17	168.365
1035.3	162.712
1038.44	167.392
1041.57	175.628
1044.7	182.863
1047.83	186.877
1050.96	193.335
1054.09	194.793
1057.21	199.14
1060.34	202.376
1063.46	203.723
1066.58	212.403
1069.7	216.639
1072.81	215.875
1075.93	224.777
1079.04	224.346
1082.15	230.804
1085.26	234.818
1088.37	237.942
1091.48	246.067
1094.59	237.192
1097.69	235.983
1100.79	237.886
1103.89	241.233
1106.99	230.691
1110.09	238.482
1113.18	229.718
1116.28	219.954
1119.37	223.745
1122.46	220.647
1125.55	214.55
1128.64	217.675
1131.72	212.355
1134.81	211.591
1137.89	200.826
1140.97	202.062
1144.05	203.631
1147.13	196.645
1150.2	200.103
1153.28	194.783
1156.35	196.352
1159.42	189.033
1162.49	193.046
1165.56	185.615
1168.62	193.073
1171.69	194.754
1174.75	185.323
1177.81	189.003
1180.87	182.128
1183.93	189.141
1186.99	184.488
1190.04	187.502
1193.09	190.849
1196.14	180.973
1199.19	178.543
1202.24	180.556
1205.29	188.792
1208.33	183.694
1211.38	185.375
1214.42	185.277
1217.46	190.513
1220.5	188.082
1223.53	193.318
1226.57	194.109
1229.6	198.234
1232.63	194.025
1235.67	203.817
1238.69	201.719
1241.72	212.399
1244.75	206.524
1247.77	207.204
1250.79	216.551
1253.81	216.787
1256.83	228.356
1259.85	222.592
1262.87	222.828
1265.88	233.397
1268.89	233.855
1271.9	249.424
1274.91	256.549
1277.92	251.673
1280.93	262.354
1283.93	289.367
1286.93	289.825
1289.94	299.283
1292.94	319.297
1295.93	336.088
1298.93	346.88
1301.93	372.671
1304.92	379.796
1307.91	441.143
1310.9	464.378
1313.89	502.503
1316.88	560.406
1319.86	614.086
1322.85	693.988
1325.83	759.891
1328.81	860.016
1331.79	971.362
1334.76	1059.04
1337.74	1116.83
1340.71	1168.74
1343.69	1151.53
1346.66	1106.54
1349.63	1032.67
1352.6	949.791
1355.56	831.582
1358.53	749.707
1361.49	676.387
1364.45	599.067
1367.41	542.303
1370.37	495.872
1373.33	460.886
1376.28	411.788
1379.23	389.913
1382.19	359.482
1385.14	342.273
1388.09	328.398
1391.03	317.412
1393.98	300.203
1396.92	284.217
1399.87	281.564
1402.81	268.355
1405.75	273.924
1408.68	258.16
1411.62	254.507
1414.55	251.743
1417.49	251.09
1420.42	247.548
1423.35	242.895
1426.28	237.797
1429.2	239.588
1432.13	243.935
1435.05	236.727
1437.97	237.962
1440.89	236.42
1443.81	237.878
1446.73	243.225
1449.65	238.906
1452.56	238.364
1455.47	235.933
1458.38	232.169
1461.29	242.516
1464.2	233.418
1467.11	229.987
1470.01	240.778
1472.92	238.57
1475.82	238.583
1478.72	243.486
1481.62	244.944
1484.51	243.624
1487.41	249.304
1490.3	249.429
1493.19	259.887
1496.08	255.79
1498.97	253.581
1501.86	260.483
1504.75	267.83
1507.63	268.844
1510.52	280.302
1513.4	277.427
1516.28	294.885
1519.15	299.787
1522.03	310.579
1524.91	318.814
1527.78	334.161
1530.65	361.73
1533.52	377.3
1536.39	408.313
1539.26	436.104
1542.12	480.896
1544.99	539.798
1547.85	605.59
1550.71	726.603
1553.57	839.061
1556.43	976.63
1559.29	1150.2
1562.14	1352.88
1565	1545.32
1567.85	1742.22
1570.7	1826.2
1573.55	1803.89
1576.39	1679.37
1579.24	1502.79
1582.08	1290.46
1584.93	1110.28
1587.77	965.391
1590.61	830.583
1593.44	751.547
1596.28	679.961
1599.12	643.164
1601.95	640.395
1604.78	633.036
1607.61	645.152
1610.44	632.649
1613.27	605.855
1616.09	545.426
1618.92	474.424
1621.74	396.233
1624.56	342.332
1627.38	307.265
1630.2	275.646
1633.02	244.996
1635.83	222.646
1638.13	208.724
1641.01	200.861
1643.9	195.665
1646.78	178.246
1649.65	179.494
1652.53	173.186
1655.41	165.768
1658.28	158.46
1661.16	153.819
1664.03	154.401
1666.9	150.093
1669.77	147.897
1672.63	142.589
1675.5	146.282
1678.36	138.307
1681.22	134.222
1684.09	139.248
1686.95	136.829
1689.8	131.633
1692.66	132.325
1695.52	130.24
1698.37	134.377
1701.22	121.736
1704.07	123.428
1706.92	124.676
1709.77	126.147
1712.62	126.283
1715.46	124.087
1718.3	118.002
1721.15	123.583
1723.99	118.498
1726.83	123.412
1729.66	120.327
1732.5	115.464
1735.33	118.379
1738.17	116.849
1741	122.652
1743.83	117.123
1746.66	113.704
1749.48	119.063
1752.31	115.978
1755.14	113.337
1757.96	109.363
1760.78	116.166
1763.6	115.192
1766.42	115.996
1769.24	116.466
1772.05	110.936
1774.87	112.517
1777.68	101.876
1780.49	110.013
1783.3	102.817
1786.11	113.843
1788.91	108.535
1791.72	109.117
1794.52	105.476
1797.33	109.724
1800.13	106.861
1802.93	104.442
1805.72	109.69
1808.52	105.827
1811.32	106.63
1814.11	107.434
1816.9	110.126
1819.69	105.819
1822.48	111.289
1825.27	108.648
1828.06	110.229
1830.84	107.811
1833.62	110.281
1836.41	103.196
1839.19	107.666
1841.97	105.692
1844.74	112.051
1847.52	108.299
1850.29	106.88
1853.07	112.128
1855.84	108.932
1858.61	109.624
1861.38	110.317
1864.15	110.454
1866.91	110.59
1869.68	114.95
1872.44	108.864
1875.2	110.112
1877.96	113.694
1880.72	114.386
1883.48	106.523
1886.24	113.882
1888.99	111.352
1891.74	105.489
1894.5	108.293
1897.25	108.43
1899.99	110.678
1902.74	107.148
1905.49	106.396
1908.23	107.755
1910.98	103.447
1913.72	103.695
1916.46	101.943
1919.2	104.969
1921.94	103.439
1924.67	106.132
1927.4	107.824
1930.14	97.6279
1932.87	96.8759
1935.6	103.457
1938.33	101.261
1941.06	100.175
1943.78	103.646
1946.51	98.4493
1949.23	104.808
1951.95	99.9453
1954.67	103.86
1957.39	100.886
1960.11	103.245
1962.82	101.16
1965.54	104.185
1968.25	101.433
1970.96	97.1258
1973.67	102.152
1976.38	102.844
1979.09	103.536
1981.8	101.229
1984.5	99.4769
1987.2	104.281
1989.9	99.6396
1992.61	105.332
1995.3	101.691
1998	104.717
2000.7	97.4094
2003.39	102.769
2006.08	104.239
2008.78	104.265
2011.47	101.957
2014.16	104.983
2016.85	109.12
2019.53	105.145
2022.22	103.505
2024.9	105.086
2027.58	101.889
2030.26	106.137
2032.94	105.385
2035.62	104.633
2038.29	103.215
2040.97	103.463
2043.64	101.155
2046.31	106.07
2048.98	98.5402
2051.65	105.233
2054.32	102.814
2056.99	103.951
2059.65	98.8655
2062.32	100.669
2064.98	102.584
2067.64	99.3873
2070.3	103.302
2072.96	96.9944
2075.61	104.02
2078.27	97.8238
2080.92	99.4051
2083.57	99.542
2086.23	97.6789
2088.88	98.9269
2091.52	98.8416
2094.17	100.978
2096.81	100.671
2099.46	100.141
2102.1	101.389
2104.74	99.7483
2107.38	99.1074
2110.02	100.244
2112.66	98.3812
2115.29	102.518
2117.93	98.8772
2120.56	96.903
2123.19	97.7066
2125.82	97.6212
2128.45	100.314
2131.08	96.2283
2133.7	96.5874
2136.33	97.5021
2138.95	93.5279
2141.57	97.1093
2144.19	93.135
2146.81	99.9386
2149.43	97.5199
2152.04	97.3235
2154.66	98.9048
2157.27	96.0418
2159.89	93.2897
2162.5	94.5378
2165.11	94.6746
2167.71	95.0338
2170.32	94.3929
2172.92	95.4187
2175.53	101.333
2178.13	98.248
2180.73	95.496
2183.33	101.522
2185.93	93.4365
2188.53	98.9067
2191.12	97.488
2193.71	95.2967
2196.31	102.29
2198.9	96.9448
2201.49	94.3975
2204.08	97.0553
2206.66	97.727
2209.25	93.8568
2211.83	96.5849
2214.42	95.3131
2217	98.5225
2219.58	98.0233
2222.16	97.6802
2224.73	94.1338
2227.31	97.2846
2229.88	98.2212
2232.46	94.6772
2235.03	96.4513
2237.6	95.8922
2240.17	96.1416
2242.74	96.643
2245.3	96.4156
2247.87	99.2606
2250.43	94.2665
2253	97.6264
2255.56	97.5164
2258.12	94.9244
2260.67	99.0824
2262.71	97.4354
2265.34	98.7948
2267.96	100.154
2270.58	98.2914
2273.2	101.762
2275.82	100.788
2278.44	102.925
2281.05	103.062
2283.67	103.866
2286.28	102.448
2288.89	103.474
2291.5	106.945
2294.11	103.637
2296.72	101.997
2299.33	108.578
2301.93	102.271
2304.53	107.964
2307.14	99.879
2309.74	102.461
2312.34	106.376
2314.94	102.402
2317.53	105.206
2320.13	111.454
2322.73	109.036
2325.32	107.617
2327.91	127.977
2330.5	113.78
2333.09	110.14
2335.68	111.055
2338.26	114.637
2340.85	114.552
2343.43	110.8
2346.02	115.604
2348.6	114.963
2351.18	114.878
2353.76	118.46
2356.33	117.041
2358.91	118.512
2361.49	117.871
2364.06	122.897
2366.63	124.924
2369.2	122.172
2371.77	125.642
2374.34	123.335
2376.91	122.917
2379.47	125.832
2382.04	128.747
2384.6	128.329
2387.16	134.799
2389.72	127.047
2392.28	136.296
2394.84	136.655
2397.4	132.126
2399.95	141.93
2402.51	143.622
2405.06	142.759
2407.61	146.674
2410.16	144.923
2412.71	150.171
2415.26	153.086
2417.8	154.89
2420.35	161.472
2422.89	163.72
2425.43	174.19
2427.97	170.328
2430.51	177.354
2433.05	175.269
2435.59	177.628
2438.12	182.543
2440.66	178.68
2443.19	179.818
2445.72	182.066
2448.26	182.981
2450.78	177.563
2453.31	176.033
2455.84	172.281
2458.36	177.196
2460.89	168.445
2463.41	164.804
2465.93	172.719
2468.45	168.301
2470.97	162.105
2473.49	165.686
2476	160.823
2478.52	158.85
2481.03	158.209
2483.55	158.791
2486.06	165.817
2488.57	162.065
2491.07	154.758
2493.58	156.451
2496.09	162.699
2498.59	156.058
2501.1	158.529
2503.6	151.666
2506.1	152.692
2508.6	157.385
2511.1	151.078
2513.59	149.993
2516.09	155.463
2518.58	149.934
2521.08	153.96
2523.57	157.319
2526.06	157.79
2528.55	149.371
2531.04	156.509
2533.52	156.646
2536.01	159.116
2538.49	152.254
2540.98	163.946
2543.46	161.417
2545.94	159.221
2548.42	159.247
2550.89	158.495
2553.37	166.855
2555.85	163.214
2558.32	163.018
2560.79	168.044
2563.26	165.515
2565.73	172.318
2568.2	165.678
2570.67	176.26
2573.14	175.063
2575.6	179.312
2578.07	178.782
2580.53	179.586
2582.99	182.612
2585.45	191.194
2587.91	194.331
2590.36	197.135
2592.82	204.717
2595.27	199.965
2597.73	205.213
2600.18	208.573
2602.63	212.488
2605.08	225.514
2607.53	227.762
2609.98	234.788
2612.42	242.481
2614.87	250.285
2617.31	255.866
2619.75	268.893
2622.19	278.585
2624.63	286.723
2627.07	306.638
2629.51	326.219
2631.94	339.467
2634.38	370.494
2636.81	380.964
2639.24	395.212
2641.67	426.794
2644.1	454.931
2646.53	475.957
2648.96	520.428
2651.38	540.121
2653.81	586.813
2656.23	633.839
2658.65	669.977
2661.07	712.669
2663.49	755.585
2665.91	810.388
2668.33	861.97
2670.74	903.774
2673.16	954.356
2675.57	988.826
2677.98	1013.3
2680.39	1065.1
2682.8	1059.57
2685.21	1064.71
2687.62	1060.4
2690.02	1018.2
2692.43	990.786
2694.83	952.368
2697.23	887.061
2699.63	843.087
2702.03	800.446
2704.43	751.028
2706.83	713.388
2709.22	642.414
2711.62	595.884
2714.01	561.688
2716.4	523.381
2718.79	489.185
2721.18	456.1
2723.57	422.237
2725.95	390.263
2728.34	368.956
2730.72	351.426
2733.11	333.564
2735.49	308.701
2737.87	293.505
2740.25	275.086
2742.63	257.001
2745	263.25
2747.38	235.387
2749.75	233.746
2752.13	218.217
2754.5	214.132
2756.87	212.713
2759.24	208.962
2761.6	196.321
2763.97	190.569
2766.34	187.262
2768.7	182.51
2771.06	184.11
2773.43	173.365
2775.79	173.565
2778.15	170.375
2780.51	171.749
2782.86	165.177
2785.22	162.793
2787.57	162.89
2789.93	158.366
2792.28	159.58
2794.63	156.416
2796.98	155.373
2799.32	159.207
2801.67	154.163
2804.02	155.916
2806.36	152.807
2808.71	150.972
2811.05	149.995
2813.39	150.27
2815.73	147.28
2818.07	151.892
2820.4	146.314
2822.74	150.005
2825.07	150.208
2827.41	148.061
2829.74	140.462
2831.81	146.675
2834.2	148.888
2836.6	148.101
2838.99	141.425
2841.38	144.637
2843.77	140.628
2846.16	145.73
2848.55	148.498
2850.94	145.711
2853.32	136.257
2855.71	147.803
2858.09	143.682
2860.48	141.228
2862.86	145.33
2865.24	142.209
2867.62	147.422
2869.99	150.413
2872.37	146.07
2874.74	145.283
2877.12	149.606
2879.49	148.041
2881.86	153.921
2884.23	147.578
2886.6	150.457
2888.97	151.67
2891.34	159.883
2893.7	161.762
2896.07	155.531
2898.43	160.966
2900.79	164.734
2903.15	166.28
2905.51	168.826
2907.87	170.483
2910.23	169.363
2912.58	178.131
2914.94	171.344
2917.29	173.334
2919.65	176.325
2922	177.315
2924.35	171.084
2926.7	174.074
2929.05	177.954
2931.39	170.5
2933.74	173.157
2936.08	169.481
2938.42	173.138
2940.77	161.128
2943.11	161.23
2945.45	159.887
2947.79	159.211
2950.12	156.868
2952.46	154.97
2954.79	151.405
2957.13	143.951
2959.46	148.83
2961.79	141.821
2964.12	135.034
2966.45	138.58
2968.78	137.126
2971.1	129.228
2973.43	129.329
2975.76	125.431
2978.08	127.644
2980.4	126.412
2982.72	117.402
2985.04	115.949
2987.36	118.939
2989.68	116.374
2991.99	111.142
2994.31	111.133
2996.62	114.679
2998.93	109.447
3001.25	111.327
3003.56	112.206
3005.87	106.419
3008.17	99.4094
3010.48	107.178
3012.79	109.39
3015.09	99.8254
3017.39	100.483
3019.7	101.695
3022	99.4637
3024.3	106.232
3026.59	102.334
3028.89	105.435
3031.19	100.537
3033.49	99.9719
3035.78	101.74
3038.07	97.5085
3040.36	104.721
3042.65	98.2673
3044.94	101.702
3047.23	99.915
3049.52	100.572
3051.8	103.785
3054.09	105.664
3056.37	101.988
3058.65	95.0899
3060.94	95.8582
3063.22	96.1821
3065.49	95.9504
3067.77	98.3854
3070.05	92.0426
3072.32	98.5886
3074.6	99.1347
3076.87	94.3475
3079.14	97.0047
3081.42	98.4396
3083.68	101.097
3085.95	97.4207
3088.22	97.6335
3090.49	99.7351
3092.75	94.7256
3095.02	96.9384
3097.28	95.4845
3099.54	100.253
3101.8	96.1322
3104.06	98.0116
3106.32	100.002
3108.57	95.9927
3110.83	96.2054
3113.08	94.4182
3115.34	96.9643
3117.59	96.7326
3119.84	99.1675
3122.09	98.9359
3124.34	98.1486
3126.59	99.6947
3128.83	96.0185
3131.08	93.7869
3133.32	100.444
3135.57	100.879
3137.81	104.203
3140.05	106.86
3142.29	99.0728
3144.53	102.952
3146.77	104.644
3149	100.482
3151.24	101.986
3153.47	100.823
3155.7	106.994
3157.94	102.943
3160.17	102.447
3162.4	97.0624
3164.62	105.122
3166.85	101.515
3169.08	101.575
3171.3	101.079
3173.53	100.139
3175.75	103.643
3177.97	102.147
3180.19	104.985
3182.41	104.489
3184.63	105.216
3186.84	103.72
3189.06	105.002
3191.27	107.617
3193.49	104.899
3195.7	111.07
3197.91	109.13
3200.12	113.967
3202.33	109.916
3204.54	114.642
3206.74	118.813
3208.95	124.762
3211.15	123.044
3213.36	130.77
3215.56	139.83
3217.76	140.001
3219.96	136.95
3222.16	143.676
3224.36	141.291
3226.55	141.684
3228.75	142.522
3230.94	142.137
3233.13	137.753
3235.33	131.479
3237.52	126.205
3239.71	124.265
3241.9	116.436
3244.08	115.496
3246.27	110.333
3248.45	101.949
3250.64	102.897
3252.82	100.179
3255	99.0169
3257.18	94.41
3259.36	99.1364
3261.54	92.1961
3263.72	96.5892
3265.9	92.4268
3268.07	88.0421
3270.24	89.5463
3272.42	87.6061
3274.59	89.6658
3276.76	82.8367
3278.93	87.7853
3281.1	86.6229
3283.26	89.2382
3285.43	87.4091
3287.59	92.2466
3289.76	84.7508
3291.92	84.9217
3294.08	85.3148
3296.24	87.0412
3298.4	84.7241
3300.56	82.0985
3302.72	84.0855
3304.87	84.1667
3307.03	87.2807
3309.18	83.8993
3311.33	86.947
3313.48	84.3685
3315.63	85.1651
3317.78	84.4681
3319.93	85.7733
3322.08	84.5444
3324.22	81.5299
3326.37	80.7998
3328.51	85.3771
3330.65	83.4038
3332.8	80.8457
3334.94	82.5112
3337.07	82.227
3339.21	82.84
3341.35	82.2856
3343.49	82.6289
3345.62	82.9216
3347.75	81.225
3349.89	86.6165
3352.02	83.0477
3353.77	79.8868
3355.96	81.8347
3358.15	86.2271
3360.34	80.3972
3362.53	80.9006
3364.72	81.0708
3366.91	85.4631
3369.09	84.9666
3371.28	77.47
3373.46	78.9734
3375.65	78.9213
3377.83	83.647
3380.01	82.5949
3382.19	81.2095
3384.37	78.9351
3386.54	80.6608
3388.72	80.942
3390.89	81.001
3393.07	84.6156
3395.24	81.4524
3397.41	79.6225
3399.58	83.4593
3401.75	83.185
3403.92	78.9106
3406.09	81.4141
3408.26	83.0286
3410.42	80.6432
3412.59	81.0355
3414.75	81.2056
3416.91	86.598
3419.07	80.7681
3421.23	76.6049
3423.39	82.3306
3425.55	83.9451
3427.71	80.4486
3429.86	80.2854
3432.02	79.4555
3434.17	83.4034
3436.32	82.1291
3438.48	80.5214
3440.63	80.2471
3442.78	81.8616
3444.92	76.0317
3447.07	82.4241
3449.22	81.0386
3451.36	78.3199
3453.51	80.49
3455.65	79.6601
3457.79	80.0524
3459.93	78.5559
3462.07	78.3927
3464.21	77.4517
3466.35	80.3996
3468.49	77.903
3470.62	80.5176
3472.76	77.4655
3474.89	81.4134
3477.02	78.6946
3479.15	78.6425
3481.28	81.1459
3483.41	74.5383
3485.54	80.8195
3487.67	80.7674
3489.79	74.493
3491.92	78.7743
3494.04	77.6111
3496.17	79.4479
3498.29	78.3958
3499.88	78.4678